#VRML_SIM R2025a utf8

EXTERNPROTO "https://raw.githubusercontent.com/cyberbotics/webots/R2023b/projects/objects/backgrounds/protos/TexturedBackground.proto"
EXTERNPROTO "https://raw.githubusercontent.com/cyberbotics/webots/R2023b/projects/objects/backgrounds/protos/TexturedBackgroundLight.proto"
EXTERNPROTO "https://raw.githubusercontent.com/cyberbotics/webots/R2023b/projects/objects/floors/protos/RectangleArena.proto"
EXTERNPROTO "https://raw.githubusercontent.com/cyberbotics/webots/R2023b/projects/devices/nvidia/protos/JetsonNano.proto"
EXTERNPROTO "https://raw.githubusercontent.com/cyberbotics/webots/R2025a/projects/objects/advertising_board/protos/AdvertisingBoard.proto"
EXTERNPROTO "https://raw.githubusercontent.com/cyberbotics/webots/R2025a/projects/objects/balls/protos/FifaSoccerBall.proto"
EXTERNPROTO "https://raw.githubusercontent.com/cyberbotics/webots/R2025a/projects/objects/traffic/protos/TrafficCone.proto"
EXTERNPROTO "https://raw.githubusercontent.com/cyberbotics/webots/R2025a/projects/objects/drinks/protos/WaterBottle.proto"
EXTERNPROTO "https://raw.githubusercontent.com/cyberbotics/webots/R2025a/projects/objects/chairs/protos/OfficeChair.proto"

WorldInfo {
}
Viewpoint {
  orientation -0.25915005156240284 0.10897602516617626 0.9596694622182081 2.374460339857002
  position 6.249804375023922 -5.711643314692152 5.619480827223726
}
TexturedBackground {
}
TexturedBackgroundLight {
}
RectangleArena {
  floorSize 5 5
}
Robot {
  translation -0.10214271647718143 0.2697477162696984 0.08630884091937449
  rotation 0.009266235501644345 -0.047933025824340135 -0.9988075700128385 -0.5591698446705493
  children [
    DEF body Solid {
      translation 2.61262e-07 -3.50352e-09 -0.0103922
      rotation -0.013408755997950201 -0.9999100985901621 1.2145376591049633e-14 2.0573649369110905e-06
      children [
        InertialUnit {
          translation -0.15 0 0.18
        }
        Lidar {
          translation -0.15 0 0.18
          rotation 0 0 1 3.141592653589793
          name "LDS-01"
          horizontalResolution 360
          fieldOfView 1.57
          numberOfLayers 1
        }
        JetsonNano {
          translation -0.01 0.01 0.16
          rotation 0 0 1 -1.5707953071795862
        }
        DEF zed_camera Pose {
          translation -0.0877 -0.0089001 0.1861
          rotation 0 0 1 -1.5707953071795862
          children [
            Shape {
              appearance PBRAppearance {
                baseColor 0.27451 0.27451 0.27451
                metalness 0
              }
              geometry Mesh {
                url [
                  "stl_files/ZED2iPikabot_ver2.STL"
                ]
              }
            }
          ]
          translationStep 0.0001
        }
        DEF caster_wheel Solid {
          translation 0.11500000000000005 -3.469446951953614e-18 -0.034000429017264605
          rotation 0.8516578705891283 0.5240981506011938 0 1.608443798445981e-09
          children [
            DEF Caster_wheel_p1 Pose {
              translation 0 0 -0.002
              children [
                HingeJoint {
                  jointParameters HingeJointParameters {
                    position -1.706768354809251
                    axis 0 0 -1
                  }
                  endPoint Solid {
                    translation 0 0 -0.031999999999999834
                    rotation 0 0 1 0.13597304602122048
                    children [
                      HingeJoint {
                        jointParameters HingeJointParameters {
                          position 521.184098135295
                          anchor 0 0.0132 0.004
                        }
                        endPoint Solid {
                          translation 0.008599999999999962 0.0132 0.004
                          rotation 0.15746763456448692 -0.1574682129764682 -0.9748885607938289 4.686955938334606
                          children [
                            Shape {
                              appearance PBRAppearance {
                                baseColor 1 0 0
                                metalness 0
                              }
                              geometry Mesh {
                                url [
                                  "stl_files/caster_wheel_P3.STL"
                                ]
                              }
                            }
                          ]
                          boundingObject Pose {
                            translation 0 0.01 3.67321e-08
                            rotation 1 0 0 1.5708
                            children [
                              Cylinder {
                                height 0.018
                                radius 0.016
                              }
                            ]
                          }
                          physics Physics {
                          }
                          translationStep 0.0001
                        }
                      }
                      Shape {
                        appearance PBRAppearance {
                        }
                        geometry Mesh {
                          url [
                            "stl_files/caster_wheel_P2.STL"
                          ]
                        }
                      }
                    ]
                    boundingObject Pose {
                      translation 0.013 0.008 0.015
                      children [
                        Box {
                          size 0.0028 0.02 0.03
                        }
                      ]
                      translationStep 0.001
                    }
                    physics Physics {
                    }
                    translationStep 0.0001
                  }
                }
                Shape {
                  appearance PBRAppearance {
                    baseColor 0.54902 0.54902 0.54902
                    metalness 0
                  }
                  geometry Mesh {
                    url [
                      "stl_files/caster_wheel_P1.STL"
                    ]
                  }
                }
              ]
              translationStep 0.0001
            }
            Shape {
              appearance PBRAppearance {
                baseColor 0.333333 1 1
                metalness 0
              }
              geometry Mesh {
                url [
                  "stl_files/casterwheel_casing.STL"
                ]
              }
            }
          ]
          name "solid(2)"
          physics Physics {
          }
          translationStep 0.0001
        }
        Shape {
          appearance PBRAppearance {
            baseColor 0.631373 0.631373 0.631373
            metalness 0
          }
          geometry Mesh {
            url [
              "stl_files/Al_Profile_Assem.STL"
            ]
          }
        }
        DEF Bumper Pose {
          translation -0.0012 0.0007 -0.0343
          children [
            DEF right_wheel HingeJoint {
              jointParameters HingeJointParameters {
                position -23.403981879029843
                axis 0 -1 0
                anchor -0.064 0.144 0
              }
              device [
                PositionSensor {
                  name "right_position_sensor"
                }
                RotationalMotor {
                  name "right_motor"
                }
              ]
              endPoint Solid {
                translation -0.06399999999811251 0.11999999999999908 1.957716399638228e-12
                rotation 0.6491111081143969 -1.0061708334136258e-06 0.7606936106748156 3.141590923817615
                children [
                  Shape {
                    appearance PBRAppearance {
                      baseColor 0.32549 0.32549 0.32549
                      metalness 0
                    }
                    geometry Mesh {
                      url [
                        "stl_files/wheel.STL"
                      ]
                    }
                  }
                ]
                name "solid(1)"
                boundingObject Pose {
                  translation 0 -0.028 -1.0285e-07
                  rotation 1 0 0 1.5708
                  children [
                    Cylinder {
                      height 0.04
                      radius 0.05
                    }
                  ]
                  translationStep 0.001
                }
                physics Physics {
                }
                translationStep 0.0001
              }
            }
            DEF left_wheel HingeJoint {
              jointParameters HingeJointParameters {
                position 112.2310140597801
                axis 0 -1 0
                anchor -0.064 -0.15 0
              }
              device [
                PositionSensor {
                  name "left_position_sensor"
                }
                RotationalMotor {
                  name "left_motor"
                }
              ]
              endPoint Solid {
                translation -0.06400000000102032 -0.12000000000000036 -1.2085064550364316e-12
                rotation 1.4317893501016411e-16 1 -1.5109997892182274e-16 4.007911469452456
                children [
                  Shape {
                    appearance PBRAppearance {
                      baseColor 0.32549 0.32549 0.32549
                      metalness 0
                    }
                    geometry Mesh {
                      url [
                        "stl_files/wheel.STL"
                      ]
                    }
                  }
                ]
                boundingObject DEF left_wheel Pose {
                  translation 0 -0.028 -2.85494e-08
                  rotation 1 0 0 -1.5707953071795862
                  children [
                    Cylinder {
                      height 0.04
                      radius 0.05
                    }
                  ]
                  translationStep 0.001
                }
                physics Physics {
                }
                translationStep 0.0001
              }
            }
            Shape {
              appearance PBRAppearance {
                baseColor 0 0.666667 1
                metalness 0
              }
              geometry Mesh {
                url [
                  "stl_files/bumper.STL"
                ]
              }
            }
          ]
          translationStep 0.0001
        }
      ]
      boundingObject DEF main_body Pose {
        translation -0.013 0 0.117
        children [
          Box {
            size 0.3 0.25 0.3
          }
        ]
        translationStep 0.001
      }
      physics Physics {
      }
    }
  ]
  name "couliglig_bot"
  physics Physics {
  }
  controller "<extern>"
}
AdvertisingBoard {
  translation 1.12192e-07 2.56 0
  rotation 0 0 1 -1.5707953071795862
  frontTexture [
    "Robec_24_25_Banner.png"
  ]
  backTexture [
    "Robec_24_25_Banner.png"
  ]
  displayWidth 5
  displayHeight 0.5
  frameThickness 0.1
  poleThickness 0.1
}
AdvertisingBoard {
  translation 2.56 0.00999291 0
  rotation 0 0 -1 -3.1415853071795863
  name "advertising board(1)"
  frontTexture [
    "Robec_24_25_Banner.png"
  ]
  backTexture [
    "Robec_24_25_Banner.png"
  ]
  displayWidth 5
  displayHeight 0.5
  frameThickness 0.1
  poleThickness 0.1
}
AdvertisingBoard {
  translation -2.56 0.00999897 0
  rotation 0 0 1 1.01503e-06
  name "advertising board(2)"
  frontTexture [
    "Robec_24_25_Banner.png"
  ]
  backTexture [
    "Robec_24_25_Banner.png"
  ]
  displayWidth 5
  displayHeight 0.5
  frameThickness 0.1
  poleThickness 0.1
}
AdvertisingBoard {
  translation -0.00999635 -2.56 0
  rotation 0 0 1 1.5708
  name "advertising board(3)"
  frontTexture [
    "Robec_24_25_Banner.png"
  ]
  backTexture [
    "Robec_24_25_Banner.png"
  ]
  displayWidth 5
  displayHeight 0.5
  frameThickness 0.1
  poleThickness 0.1
}
FifaSoccerBall {
  translation 1.51 0 0.12
}
TrafficCone {
  translation 1.49 1.64 0
}
TrafficCone {
  translation -0.33 -1.36 0
  name "traffic cone(1)"
}
TrafficCone {
  translation -0.75 1.1 0
  name "traffic cone(2)"
}
WaterBottle {
  translation 1.02 -0.52 0
}
OfficeChair {
  translation -1.7 -0.74 0
}
